Running FedStream with: Dir=1.0, Init_Class=10, Epoch=20
Files already downloaded and verified
Files already downloaded and verified
has read
Files already downloaded and verified
Files already downloaded and verified
  0%|          | 0/100 [00:00<?, ?it/s]  0%|          | 0/100 [00:00<?, ?it/s]
10 77 [8 3 7 5 4 1 2 6 0 9]
Traceback (most recent call last):
  File "/home/kemove/lt/FedAlgorithm/alg/FedStream.py", line 770, in <module>
    alg.online_train()
  File "/home/kemove/lt/FedAlgorithm/alg/FedStream.py", line 733, in online_train
    global_loss_list, accuracy_list = self.alg.run(
                                      ^^^^^^^^^^^^^
  File "/home/kemove/lt/FedAlgorithm/alg/FedProx.py", line 113, in run
    result = self.client_group.clients[k].local_update_prox(
             ^^^^^^^^^^^^^^^^^^^^^^^^^^^^^^^^^^^^^^^^^^^^^^^
  File "/home/kemove/lt/FedAlgorithm/alg/Clients.py", line 239, in local_update_prox
    pred = self.net(data)
           ^^^^^^^^^^^^^^
  File "/home/kemove/anaconda3/envs/test/lib/python3.11/site-packages/torch/nn/modules/module.py", line 1532, in _wrapped_call_impl
    return self._call_impl(*args, **kwargs)
           ^^^^^^^^^^^^^^^^^^^^^^^^^^^^^^^^
  File "/home/kemove/anaconda3/envs/test/lib/python3.11/site-packages/torch/nn/modules/module.py", line 1541, in _call_impl
    return forward_call(*args, **kwargs)
           ^^^^^^^^^^^^^^^^^^^^^^^^^^^^^
  File "/home/kemove/lt/FedAlgorithm/alg/../model/cifar100.py", line 26, in forward
    return self.model(x)
           ^^^^^^^^^^^^^
  File "/home/kemove/anaconda3/envs/test/lib/python3.11/site-packages/torch/nn/modules/module.py", line 1532, in _wrapped_call_impl
    return self._call_impl(*args, **kwargs)
           ^^^^^^^^^^^^^^^^^^^^^^^^^^^^^^^^
  File "/home/kemove/anaconda3/envs/test/lib/python3.11/site-packages/torch/nn/modules/module.py", line 1541, in _call_impl
    return forward_call(*args, **kwargs)
           ^^^^^^^^^^^^^^^^^^^^^^^^^^^^^
  File "/home/kemove/anaconda3/envs/test/lib/python3.11/site-packages/torchvision/models/resnet.py", line 285, in forward
    return self._forward_impl(x)
           ^^^^^^^^^^^^^^^^^^^^^
  File "/home/kemove/anaconda3/envs/test/lib/python3.11/site-packages/torchvision/models/resnet.py", line 269, in _forward_impl
    x = self.bn1(x)
        ^^^^^^^^^^^
  File "/home/kemove/anaconda3/envs/test/lib/python3.11/site-packages/torch/nn/modules/module.py", line 1532, in _wrapped_call_impl
    return self._call_impl(*args, **kwargs)
           ^^^^^^^^^^^^^^^^^^^^^^^^^^^^^^^^
  File "/home/kemove/anaconda3/envs/test/lib/python3.11/site-packages/torch/nn/modules/module.py", line 1541, in _call_impl
    return forward_call(*args, **kwargs)
           ^^^^^^^^^^^^^^^^^^^^^^^^^^^^^
  File "/home/kemove/anaconda3/envs/test/lib/python3.11/site-packages/torch/nn/modules/batchnorm.py", line 155, in forward
    self.num_batches_tracked.add_(1)  # type: ignore[has-type]
    ^^^^^^^^^^^^^^^^^^^^^^^^^^^^^^^^
RuntimeError: CUDA error: out of memory
CUDA kernel errors might be asynchronously reported at some other API call, so the stacktrace below might be incorrect.
For debugging consider passing CUDA_LAUNCH_BLOCKING=1.
Compile with `TORCH_USE_CUDA_DSA` to enable device-side assertions.

