Running FedStream with: Dir=0.5, Init_Class=10, Epoch=30
Files already downloaded and verified
Files already downloaded and verified
has read
Files already downloaded and verified
Files already downloaded and verified
  0%|          | 0/100 [00:00<?, ?it/s]  0%|          | 0/100 [01:20<?, ?it/s]
5 154 [8 0 4 3 9]
5 140 [5 8 3 9 2]
5 150 [0 6 9 3 2]
5 152 [0 6 1 3 2]
5 154 [3 5 6 7 0]
Traceback (most recent call last):
  File "/home/kemove/lt/FedAlgorithm/alg/FedStream.py", line 770, in <module>
    alg.online_train()
  File "/home/kemove/lt/FedAlgorithm/alg/FedStream.py", line 733, in online_train
    global_loss_list, accuracy_list = self.alg.run(
                                      ^^^^^^^^^^^^^
  File "/home/kemove/lt/FedAlgorithm/alg/FedProx.py", line 161, in run
    pred = self.net(data)  # [batch_size， 10]，输出的是概率
           ^^^^^^^^^^^^^^
  File "/home/kemove/anaconda3/envs/test/lib/python3.11/site-packages/torch/nn/modules/module.py", line 1532, in _wrapped_call_impl
    return self._call_impl(*args, **kwargs)
           ^^^^^^^^^^^^^^^^^^^^^^^^^^^^^^^^
  File "/home/kemove/anaconda3/envs/test/lib/python3.11/site-packages/torch/nn/modules/module.py", line 1541, in _call_impl
    return forward_call(*args, **kwargs)
           ^^^^^^^^^^^^^^^^^^^^^^^^^^^^^
  File "/home/kemove/lt/FedAlgorithm/alg/../model/cifar10.py", line 36, in forward
    x = self.conv_block(x)
        ^^^^^^^^^^^^^^^^^^
  File "/home/kemove/anaconda3/envs/test/lib/python3.11/site-packages/torch/nn/modules/module.py", line 1532, in _wrapped_call_impl
    return self._call_impl(*args, **kwargs)
           ^^^^^^^^^^^^^^^^^^^^^^^^^^^^^^^^
  File "/home/kemove/anaconda3/envs/test/lib/python3.11/site-packages/torch/nn/modules/module.py", line 1541, in _call_impl
    return forward_call(*args, **kwargs)
           ^^^^^^^^^^^^^^^^^^^^^^^^^^^^^
  File "/home/kemove/anaconda3/envs/test/lib/python3.11/site-packages/torch/nn/modules/container.py", line 217, in forward
    input = module(input)
            ^^^^^^^^^^^^^
  File "/home/kemove/anaconda3/envs/test/lib/python3.11/site-packages/torch/nn/modules/module.py", line 1532, in _wrapped_call_impl
    return self._call_impl(*args, **kwargs)
           ^^^^^^^^^^^^^^^^^^^^^^^^^^^^^^^^
  File "/home/kemove/anaconda3/envs/test/lib/python3.11/site-packages/torch/nn/modules/module.py", line 1541, in _call_impl
    return forward_call(*args, **kwargs)
           ^^^^^^^^^^^^^^^^^^^^^^^^^^^^^
  File "/home/kemove/anaconda3/envs/test/lib/python3.11/site-packages/torch/nn/modules/conv.py", line 460, in forward
    return self._conv_forward(input, self.weight, self.bias)
           ^^^^^^^^^^^^^^^^^^^^^^^^^^^^^^^^^^^^^^^^^^^^^^^^^
  File "/home/kemove/anaconda3/envs/test/lib/python3.11/site-packages/torch/nn/modules/conv.py", line 456, in _conv_forward
    return F.conv2d(input, weight, bias, self.stride,
           ^^^^^^^^^^^^^^^^^^^^^^^^^^^^^^^^^^^^^^^^^^
torch.cuda.OutOfMemoryError: CUDA out of memory. Tried to allocate 256.00 MiB. GPU 
