Running FedStream with: Dir=0.8, Init_Class=10, Epoch=20
Files already downloaded and verified
Files already downloaded and verified
has read
Files already downloaded and verified
Files already downloaded and verified
  0%|          | 0/100 [00:00<?, ?it/s]  0%|          | 0/100 [00:00<?, ?it/s]
8 96 [8 0 4 3 9 1 2 6]
Traceback (most recent call last):
  File "/home/kemove/lt/FedAlgorithm/alg/FedStream.py", line 775, in <module>
    alg.online_train()
  File "/home/kemove/lt/FedAlgorithm/alg/FedStream.py", line 738, in online_train
    global_loss_list, accuracy_list = self.alg.run(
                                      ^^^^^^^^^^^^^
  File "/home/kemove/lt/FedAlgorithm/alg/FedProx.py", line 113, in run
    result = self.client_group.clients[k].local_update_prox(
             ^^^^^^^^^^^^^^^^^^^^^^^^^^^^^^^^^^^^^^^^^^^^^^^
  File "/home/kemove/lt/FedAlgorithm/alg/Clients.py", line 240, in local_update_prox
    pred = self.net(data)
           ^^^^^^^^^^^^^^
  File "/home/kemove/anaconda3/envs/test/lib/python3.11/site-packages/torch/nn/modules/module.py", line 1532, in _wrapped_call_impl
    return self._call_impl(*args, **kwargs)
           ^^^^^^^^^^^^^^^^^^^^^^^^^^^^^^^^
  File "/home/kemove/anaconda3/envs/test/lib/python3.11/site-packages/torch/nn/modules/module.py", line 1541, in _call_impl
    return forward_call(*args, **kwargs)
           ^^^^^^^^^^^^^^^^^^^^^^^^^^^^^
  File "/home/kemove/lt/FedAlgorithm/alg/../model/cifar10.py", line 36, in forward
    x = self.conv_block(x)
        ^^^^^^^^^^^^^^^^^^
  File "/home/kemove/anaconda3/envs/test/lib/python3.11/site-packages/torch/nn/modules/module.py", line 1532, in _wrapped_call_impl
    return self._call_impl(*args, **kwargs)
           ^^^^^^^^^^^^^^^^^^^^^^^^^^^^^^^^
  File "/home/kemove/anaconda3/envs/test/lib/python3.11/site-packages/torch/nn/modules/module.py", line 1541, in _call_impl
    return forward_call(*args, **kwargs)
           ^^^^^^^^^^^^^^^^^^^^^^^^^^^^^
  File "/home/kemove/anaconda3/envs/test/lib/python3.11/site-packages/torch/nn/modules/container.py", line 217, in forward
    input = module(input)
            ^^^^^^^^^^^^^
  File "/home/kemove/anaconda3/envs/test/lib/python3.11/site-packages/torch/nn/modules/module.py", line 1532, in _wrapped_call_impl
    return self._call_impl(*args, **kwargs)
           ^^^^^^^^^^^^^^^^^^^^^^^^^^^^^^^^
  File "/home/kemove/anaconda3/envs/test/lib/python3.11/site-packages/torch/nn/modules/module.py", line 1541, in _call_impl
    return forward_call(*args, **kwargs)
           ^^^^^^^^^^^^^^^^^^^^^^^^^^^^^
  File "/home/kemove/anaconda3/envs/test/lib/python3.11/site-packages/torch/nn/modules/conv.py", line 460, in forward
    return self._conv_forward(input, self.weight, self.bias)
           ^^^^^^^^^^^^^^^^^^^^^^^^^^^^^^^^^^^^^^^^^^^^^^^^^
  File "/home/kemove/anaconda3/envs/test/lib/python3.11/site-packages/torch/nn/modules/conv.py", line 456, in _conv_forward
    return F.conv2d(input, weight, bias, self.stride,
           ^^^^^^^^^^^^^^^^^^^^^^^^^^^^^^^^^^^^^^^^^^
RuntimeError: CUDA error: out of memory
CUDA kernel errors might be asynchronously reported at some other API call, so the stacktrace below might be incorrect.
For debugging consider passing CUDA_LAUNCH_BLOCKING=1.
Compile with `TORCH_USE_CUDA_DSA` to enable device-side assertions.

